Workbook

Sheet notification
A1: notification_no | B1: notification_type | C1: notification_date | D1: maintenance_plant | E1: target_date | F1: maint_work_centre | G1: reported_by | H1: work_order_no | I1: assigned_to | J1: parent_work_order_no | K1: system_status | L1: user_status | M1: functional_location | N1: location | O1: superior_equipment | P1: equipment | Q1: coding | R1: work_request | S1: description | T1: tasks | U1: staff_details | V1: comments | W1: object_part_items | X1: cause_items | Y1: activity_items | Z1: date_closed | AA1: supervisor_verification | AB1: filename
A2: 11895192 | B2: M7 | C2: 11/01/2022 | D2: 0805 | E2: 17/01/2022 | F2: WS10 | G2: IP1020220111 | H2: 4000444211 | K2: NOPR ORAS | L2: REQ | M2: PRAL-MRL-WS-STN-MRLTSA Station Titiwangsa | N2: WES Wayside Department | Q2: MRWSU001 1003 | R2: PM Inspection for Titiwangsa | S2: PM Inspection for Titiwangsa | T2: [] | U2: [] | V2: Pm complete | W2: [] | X2: [] | Y2: [] | Z2: 17/01/20222 | AA2: 7091 | AB2: PS_PM_WEK_StationInspection_4000444211.pdf
A3: 11893905 | B3: M7 | C3: 06/01/2022 | D3: 0805 | E3: 12/01/2022 | F3: WS10 | G3: IP1020220106 | H3: 4000443612 | K3: NOPR ORAS | L3: REQ | M3: PRAL-MRL-WS-STN-MRLBNG Station Bukit Bintang | N3: WES Wayside Department | Q3: MRWSU001 1003 | R3: PM Inspection for Bukit Bintang Station | S3: PM Inspection for Bukit Bintang Station | T3: [] | U3: [{'staff_id': '', 'name': 'AT MS', 'plan_start_date_time': '', 'plan_end_date_time': '', 'total_hours': ''}] | V3: PM Complete | W3: [] | X3: [] | Y3: [] | Z3: 12/01/2022 | AA3: 7099 | AB3: PS_PM_WEK_StationInspection_4000443612.pdf
A4: 11900696 | B4: M7 | C4: 28/01/2022 | D4: 0805 | E4: 03/02/2022 | F4: WS10 | G4: IP1020220128 | H4: 4000448495 | K4: NOPR ORAS | L4: REQ | M4: PRAL-MRL-WS-STN-MRLIBI Station Imbi | N4: WES Wayside Department | Q4: MRWSU001 1003 | R4: PM Inspection for Imbi Station | S4: PM Inspection for Imbi Station | T4: [] | U4: [] | V4: pm complete | W4: [] | X4: [] | Y4: [] | Z4: 03/02/2022 | AA4: 7013 | AB4: PS_PM_WEK_StationInspection_4000448495.pdf
A5: 12407769 | B5: M7 | C5: 13/02/2025 | D5: 0805 | E5: 20/02/2025 | F5: WS10 | G5: IP1020250213 | H5: 4000657499 | K5: NOPR NOPT ORAS OSTS | L5: CLS ACK | M5: PRAL-MRL-WS-STN-MRLHAH Station Hang Tuah | N5: WES Wayside Department | Q5: MRWSU001 1006 Inspection - 3 Months Interval | R5: PM Inspection for Hang Tuah Station | S5: - PM COMPLETE | T5: [{'task': '0001', 'description': '1001'}] | U5: [{'staff_id': '10019924', 'name': 'AHMAD JURIJ BIN AMIRUDIN', 'plan_start_date_time': '00:00:00', 'plan_end_date_time': '00:00:00', 'total_hours': ''}] | W5: [{'item': '0001', 'object_part': 'Station Power Supply', 'damage': ''}] | X5: [{'item': '0001', 'cause': 'Scheduled maintenance'}] | Y5: [{'item': '0001', 'activity': 'Check/Inspect -'}] | Z5: 20/02/2025 | AA5: 19924 | AB5: PS_PM_QTR_StationInspection_4000657499.pdf
A6: 12398339 | B6: M7 | C6: 23/01/2025 | D6: 0805 | E6: 30/01/2025 | F6: WS10 | G6: IP1020250123 | H6: 4000654182 | K6: NOPR NOPT ORAS OSTS | L6: CLS ACK | M6: PRAL-MRL-WS-STN-MRLHAH Station Hang Tuah | N6: WES Wayside Department | Q6: MRWSU001 1006 Inspection - 3 Months Interval | R6: PM Inspection for Hang Tuah Station | S6: PM COMPLETE | T6: [{'task': '0001', 'description': '1001'}] | U6: [{'staff_id': '10019234', 'name': 'MOHAMAD NORIEZUWADI BIN ZUL', 'plan_start_date_time': '00:00:00', 'plan_end_date_time': '00:00:00', 'total_hours': ''}] | V6: pm complete | W6: [{'item': '0001', 'object_part': 'Building Power Supply', 'damage': ''}] | X6: [{'item': '0001', 'cause': 'Scheduled maintenance'}] | Y6: [{'item': '0001', 'activity': 'Check / Inspect -'}] | Z6: 30/01/2025 | AA6: 19234 | AB6: PS_PM_QTR_StationInspection_4000654182.pdf
A7: 12407193 | B7: M7 | C7: 11/02/2025 | D7: 0805 | E7: 18/02/2025 | F7: WS10 | G7: IP1020250211 | H7: 4000657494 | K7: NOPR NOPT ORAS OSTS | L7: CLS ACK | M7: PRAL-MRL-WS-STN-MRLBAS Station Bukit Nanas | N7: WES Wayside Department | Q7: MRWSU001 1006 Inspection - 3 Months Interval | R7: PM Inspection for Bukit Nanas Station | S7: - PM COMPLETE | T7: [{'task': '0001', 'description': '1001'}] | U7: [{'staff_id': '10019924', 'name': 'AHMAD JURIJ BIN AMIRUDIN', 'plan_start_date_time': '00:00:00', 'plan_end_date_time': '00:00:00', 'total_hours': ''}] | V7: Pm Complete | W7: [{'item': '0001', 'object_part': 'Station Power Supply', 'damage': ''}] | X7: [{'item': '0001', 'cause': 'Scheduled maintenance', 'NA': ''}] | Y7: [{'item': '0001', 'activity': 'Check / Inspect -', 'NA': ''}] | Z7: 19/3/25 | AA7: 7114 | AB7: PS_PM_QTR_StationInspection_4000657494.pdf
A8: 12407194 | B8: M7 | C8: 11/02/2025 | D8: 0805 | E8: 18/02/2025 | F8: WS10 | G8: IP1020250211 | H8: 4000657493 | I8: NOPR NOPT ORAS OSTS | L8: CLS ACK | M8: PRAL-MRL-WS-STN-MRLMKU Station Medan Tuanku | N8: WES Wayside Department | Q8: MRWSU001 1006 Inspection - 3 Months Interval | R8: PM Inspection for Medan Tuanku Station | S8: - PM COMPLETE | T8: [{'task': '0001', 'description': '1001'}] | U8: [{'staff_id': '10019924', 'name': 'AHMAD JURIJ BIN AMIRUDIN', 'plan_start_date_time': '00:00:00', 'plan_end_date_time': '00:00:00', 'total_hours': ''}] | V8: Pm Complete | W8: [{'item': '0001', 'object_part': 'Station Power Supply', 'damage': ''}] | X8: [{'item': '0001', 'cause': 'Scheduled maintenance'}] | Y8: [{'item': '0001', 'activity': 'Check / Inspect -'}] | Z8: 18/02/2025 | AA8: 7114 | AB8: PS_PM_QTR_StationInspection_4000657493.pdf
A9: 12407770 | B9: M7 | C9: 13/02/2025 | D9: 0805 | E9: 20/02/2025 | F9: WS10 | G9: IP1020250213 | H9: 4000657498 | K9: NOPR NOPT ORAS OSTS | L9: CLS ACK | M9: PRAL-MRL-WS-STN-MRLIBI Station Imbi | N9: WES Wayside Department | Q9: MRWSU001 1006 Inspection - 3 Months Interval | R9: PM Inspection for Imbi Station | S9: - PM COMPLETE | T9: [{'task': '0001', 'description': '1001'}] | U9: [{'staff_id': '10019924', 'name': 'AHMAD JURIJ BIN AMIRUDIN', 'plan_start_date_time': '00:00:00', 'plan_end_date_time': '00:00:00', 'total_hours': ''}] | V9: Pm Complete | W9: [{'item': '0001', 'object_part': 'Station Power Supply', 'damage': ''}] | X9: [{'item': '0001', 'cause': 'Scheduled maintenance'}] | Y9: [{'item': '0001', 'activity': 'Check/Inspect -'}] | Z9: 20/02/2025 | AA9: 19924 | AB9: PS_PM_QTR_StationInspection_4000657498.pdf
A10: 12408388 | B10: M7 | C10: 14/02/2025 | D10: 0805 | E10: 21/02/2025 | F10: WS10 | G10: IP1020250214 | H10: 4000657936 | K10: NOPR NOPT ORAS OSTS | L10: CLS ACK | M10: PRAL-MRL-WS-STN-MRLMAH Station Maharajalela | N10: WES Wayside Department | Q10: MRWSU001 1006 Inspection - 3 Months Interval | R10: PM Inspection for Maharaja Lela Station | S10: - PM COMPLETE | T10: [{'task': '0001', 'description': '1001'}] | U10: [{'staff_id': '10011858', 'name': 'NAZRULSHAH BIN MOHAMAD JUBERI', 'plan_start_date_time': '00:00:00', 'plan_end_date_time': '00:00:00', 'total_hours': ''}] | V10: PM Complete | W10: [{'item': '0001', 'object_part': 'Station Power Supply', 'damage': ''}] | X10: [{'item': '0001', 'cause': 'Scheduled maintenance'}] | Y10: [{'item': '0001', 'activity': 'Check/Inspect -'}] | Z10: 21/02/2025 | AA10: 11858 | AB10: PS_PM_QTR_StationInspection_4000657936.pdf
A11: 11910493 | B11: M7 | C11: 18/02/2022 | D11: 0805 | E11: 24/02/2022 | F11: WS10 | G11: IP1020220218 | H11: 4000450788 | K11: NOPR ORAS | L11: REQ | M11: PRAL-MRL-WS-STN-MRLHAH Station Hang Tuah | N11: WES Wayside Department | Q11: MRWSU001 1003 | R11: PM Inspection for Hang Tuah Station | S11: PM Inspection for Hang Tuah Station | T11: [] | U11: [] | V11: pm complete | W11: [] | X11: [] | Y11: [] | Z11: 24/02/2022 | AA11: 7013 | AB11: PS_PM_WEK_StationInspection_4000450788.pdf
A12: 12380825 | B12: M7 | C12: 12/12/2024 | D12: 0805 | E12: 19/12/2024 | F12: WS10 | G12: IP1020241212 | H12: 4000655145 | K12: NOPR NOPT ORAS OSTS | L12: CLS ACK | M12: PRAL-MRL-WS-STN-MRLHAH Station Hang Tuah | N12: WES Wayside Department | Q12: MRWSU001 1003 Inspection - 1 Week Interval | R12: PM Inspection for Hang Tuah Station | S12: PM COMPLETE | T12: [{'task': '0001', 'description': '1001'}] | U12: [{'staff_id': '10012660', 'name': 'MUHAMAD SHAZWAN BIN\nMOHAMMAD RASUDIN', 'plan_start_date_time': '00:00:00', 'plan_end_date_time': '00:00:00', 'total_hours': ''}] | V12: Pm complete. | W12: [{'item': '0001', 'object_part': 'Station Power Supply', 'damage': ''}] | X12: [{'item': '0001', 'cause': 'Scheduled maintenance'}] | Y12: [{'item': '0001', 'activity': 'Check / Inspect -'}] | Z12: 12/12/2024 | AA12: 7114 | AB12: PS_PM_WEK_StationInspection_4000655145.pdf
A13: 12380206 | B13: M7 | C13: 10/12/2024 | D13: 0805 | E13: 17/12/2024 | F13: WS10 | G13: IP1020241210 | H13: 4000655120 | K13: NOPR NOPT ORAS OSTS | L13: CLS ACK | M13: PRAL-MRL-WS-STN-MRLBAS Station Bukit Nanas | N13: WES Wayside Department | Q13: MRWSU001 1003 Inspection - 1 Week Interval | R13: PM Inspection for Bukit Nanas Station | S13: PM COMPLETE | T13: [{'task': '0001', 'description': '1001'}] | U13: [{'staff_id': '10012660', 'name': 'MUHAMAD SHAZWAN BIN\nMOHAMMAD RASUDIN', 'plan_start_date_time': '00:00:00', 'plan_end_date_time': '00:00:00', 'total_hours': ''}] | V13: Pm complete. | W13: [{'item': '0001', 'object_part': 'Station Power Supply', 'damage': ''}] | X13: [{'item': '0001', 'cause': 'Scheduled maintenance'}] | Y13: [{'item': '0001', 'activity': 'Check / Inspect -'}] | Z13: 17/12/2024 | AB13: PS_PM_WEK_StationInspection_4000655120.pdf
A14: 12380941 | B14: M7 | C14: 13/12/2024 | D14: 0805 | E14: 20/12/2024 | F14: WS10 | G14: IP1020241213 | H14: 4000655149 | K14: NOPR NOPT ORAS OSTS | L14: CLS ACK | M14: PRAL-MRL-WS-STN-MRLTUN Station Tun Sambanthan | N14: WES Wayside Department | Q14: MRWSU001 1003 Inspection - 1 Week Interval | R14: PM Inspection for Tun Sambanthan Station | S14: PM COMPLETE | T14: [{'task': '0001', 'description': '1001'}] | U14: [{'staff_id': '10007094', 'name': 'MOHAMAD IRZAN BIN YUSOF', 'plan_start_date_time': '00:00:00', 'plan_end_date_time': '00:00:00', 'total_hours': ''}] | V14: pm complete. | W14: [{'item': '0001', 'object_part': 'Station Power Supply', 'damage': ''}] | X14: [{'item': '0001', 'cause': 'Scheduled maintenance'}] | Y14: [{'item': '0001', 'activity': 'Check/Inspect -'}] | Z14: 13/12/2024 | AA14: 19234 | AB14: PS_PM_WEK_StationInspection_4000655149.pdf
A15: 12381875 | B15: M7 | C15: 16/12/2024 | D15: 0805 | E15: 23/12/2024 | F15: WS10 | G15: IP1020241216 | H15: 4000655156 | K15: NOPR NOPT ORAS OSTS | L15: CLS ACK | M15: PRAL-MRL-WS-STN-MRLCIT Station Chow Kit | N15: WES Wayside Department | Q15: MRWSU001 1003 Inspection - 1 Week Interval | R15: PM Inspection for Chow Kit Station | S15: - PM COMPLETE | T15: [{'task': '0001', 'description': '1001'}] | U15: [{'staff_id': '10019234', 'name': 'MOHAMAD NORIEZUWADI BIN ZUL', 'plan_start_date_time': '00:00:00', 'plan_end_date_time': '00:00:00', 'total_hours': ''}] | V15: Pm complete | W15: [{'item': '0001', 'object_part': 'Station Power Supply', 'damage': ''}] | X15: [{'item': '0001', 'cause': 'Scheduled maintenance'}] | Y15: [{'item': '0001', 'activity': 'Check/Inspect -'}] | Z15: 16/12/24 | AA15: 19234 | AB15: PS_PM_WEK_StationInspection_4000655156.pdf
A16: 12408387 | B16: M7 | C16: 14/02/2025 | D16: 0805 | E16: 21/02/2025 | F16: WS10 | G16: IP1020250214 | H16: 4000657933 | K16: NOPR NOPT ORAS | L16: REQ | M16: PRAL-MRL-WS-TPS-MRLHTZ TPSS - Hang Tuah | N16: WES Wayside Department | Q16: MRWSU001 I006 Inspection - 3 Months Interval | R16: PM Inspection for Hang Tuah TPSS | T16: [] | U16: [] | V16: PM Complete | W16: [] | X16: [] | Y16: [] | Z16: 21/02/2025 | AA16: 11858 | AB16: PS_PM_QTR_TPSS_4000657933.pdf
A17: 11899188 | B17: M7 | C17: 22/01/2022 | D17: 0805 | E17: 28/01/2022 | F17: WS10 | G17: IP1020220122 | H17: 4000446655 | K17: NOPR ORAS | L17: REQ | M17: PRAL-MRL-WS-STN-MRLTUN Station Tun Sambanthan | N17: WES Wayside Department | Q17: MRWSU001 1003 | R17: PM Inspection for Tun Sambanthan Station | S17: PM Inspection for Tun Sambanthan Station | T17: [] | U17: [{'staff_id': '', 'name': 'Ad, ms', 'plan_start_date_time': '', 'plan_end_date_time': '', 'total_hours': ''}] | V17: Pm Complete | W17: [] | X17: [] | Y17: [] | Z17: 28/01/2022 | AA17: 7099 | AB17: PS_PM_WEK_StationInspection_4000446655.pdf
A18: 12383049 | B18: M7 | C18: 18/12/2024 | D18: 0805 | E18: 25/12/2024 | F18: WS20 | G18: IP1020241218 | H18: 4000655162 | K18: NOPR NOPT ORAS OSTS | L18: CLS ACK | M18: PRAL-MRL-WS-STN-MRLRAN Station Raja Chulan | N18: WES Wayside Department | Q18: MRWSU001 I003 Inspection - 1 Week Interval | S18: - PM COMPLETE | T18: [{'task': '0001', 'description': 'I001'}] | U18: [{'staff_id': '10019234', 'name': 'MOHAMAD NORIEZUWADI BIN ZUL', 'plan_start_date_time': '00:00:00', 'plan_end_date_time': '00:00:00', 'total_hours': ''}] | V18: Pm complete. | W18: [{'item': '0001', 'object_part': 'Station Power Supply', 'damage': ''}] | X18: [{'item': '0001', 'cause': 'Scheduled maintenance'}] | Y18: [{'item': '0001', 'activity': 'Check/Inspect -'}] | Z18: 18/12/24 | AA18: 19234 | AB18: PS_PM_WEK_StationInspection_4000655162.pdf
A19: 12382397 | B19: M7 | C19: 17/12/2024 | D19: 0805 | E19: 24/12/2024 | F19: WS10 | G19: IP1020241217 | H19: 4000655158 | K19: NOPR NOPT ORAS OSTS | L19: CLS ACK | M19: PRAL-MRL-WS-STN-MRLBAS Station Bukit Nanas | N19: WES Wayside Department | Q19: MRWSU001 1003 Inspection - 1 Week Interval | R19: PM Inspection for Bukit Nanas Station | S19: - PM COMPLETE | T19: [{'task': '0001', 'description': '1001'}] | U19: [{'staff_id': '10019234', 'name': 'MOHAMAD NORIEZUWADI BIN ZUL', 'plan_start_date_time': '00:00:00', 'plan_end_date_time': '00:00:00', 'total_hours': ''}] | V19: Pm complete. | W19: [{'item': '0001', 'object_part': 'Station Power Supply', 'damage': ''}] | X19: [{'item': '0001', 'cause': 'Scheduled maintenance'}] | Y19: [{'item': '0001', 'activity': 'Check / Inspect -'}] | Z19: 17/12/2024 | AA19: 19234 | AB19: PS_PM_WEK_StationInspection_4000655158.pdf
A20: 12383394 | B20: M7 | C20: 19/12/2024 | D20: 0805 | E20: 26/12/2024 | F20: WS10 | G20: IP1020241219 | H20: 4000655163 | K20: NOPR NOPT ORAS OSTS | L20: CLS ACK | M20: PRAL-MRL-WS-STN-MRLHAH Station Hang Tuah | N20: WES Wayside Department | Q20: MRWSU001 I003 Inspection - 1 Week Interval | R20: PM Inspection for Hang Tuah Station | S20: - PM COMPLETE | T20: [{'task': '0001', 'description': 'I001'}] | U20: [{'staff_id': '10019924', 'name': 'AHMAD JURIJ BIN AMIRUDIN', 'plan_start_date_time': '00:00:00', 'plan_end_date_time': '00:00:00', 'total_hours': ''}] | V20: Pm complete. | W20: [{'item': '0001', 'object_part': 'Station Power Supply', 'damage': ''}] | X20: [{'item': '0001', 'cause': 'Scheduled maintenance'}] | Y20: [{'item': '0001', 'activity': 'Check/Inspect -'}] | Z20: 19/12/2024 | AA20: 19234 | AB20: PS_PM_WEK_StationInspection_4000655163.pdf
A21: 12383735 | B21: M7 | C21: 20/12/2024 | D21: 0805 | E21: 27/12/2024 | F21: WS10 | G21: IP1020241220 | H21: 4000655167 | K21: NOPR NOPT ORAS OSTS | L21: CLS ACK | M21: PRAL-MRL-WS-STN-MRLTUN Station Tun Sambanthan | N21: WES Wayside Department | Q21: MRWSU001 1003 Inspection - 1 Week Interval | R21: PM Inspection for Tun Sambanthan Station | S21: - PM COMPLETE | T21: [{'task': '0001', 'description': '1001'}] | U21: [{'staff_id': '10019924', 'name': 'AHMAD JURIJ BIN AMIRUDIN', 'plan_start_date_time': '00:00:00', 'plan_end_date_time': '00:00:00', 'total_hours': '1'}] | V21: PM Complete. | W21: [{'item': '0001', 'object_part': 'Station Power Supply', 'damage': ''}] | X21: [{'item': '0001', 'cause': 'Scheduled maintenance'}] | Y21: [{'item': '0001', 'activity': 'Check / Inspect -'}] | Z21: 2O/12/2024 | AA21: 19234 | AB21: PS_PM_WEK_StationInspection_4000655167.pdf
A22: 12383395 | B22: M7 | C22: 19/12/2024 | D22: 0805 | E22: 26/12/2024 | F22: WS10 | G22: IP1020241219 | H22: 4000655164 | K22: NOPR NOPT ORAS OSTS | L22: CLS ACK | M22: PRAL-MRL-WS-STN-MRLIBI Station Imbi | N22: WES Wayside Department | Q22: MRWSU001 1003 | R22: Inspection - 1 Week Interval | S22: PM Inspection for Imbi Station - PM COMPLETE | T22: [{'task': '0001', 'description': '1001'}] | U22: [{'staff_id': '10019924', 'name': 'AHMAD JURIJ BIN AMIRUDIN', 'plan_start_date_time': '00:00:00', 'plan_end_date_time': '00:00:00', 'total_hours': ''}] | V22: Pm complete. | W22: [{'item': '0001', 'object_part': 'Station Power Supply', 'damage': ''}] | X22: [{'item': '0001', 'cause': 'Scheduled maintenance'}] | Y22: [{'item': '0001', 'activity': 'Check / Inspect -'}] | Z22: 26/12/2024 | AA22: 19234 | AB22: PS_PM_WEK_StationInspection_4000655164.pdf
A23: 11908773 | B23: M7 | C23: 13/02/2022 | D23: 0805 | E23: 19/02/2022 | F23: WS10 | G23: IP1020220213 | H23: 4000449980 | K23: NOPR ORAS | L23: REQ | M23: PRAL-MRL-WS-TPS-MRLSSZ TPSS - Sultan Sulaiman | N23: WES Wayside Department | Q23: MRWSU001 1003 | R23: PM Inspection for Sultan Sulaiman TPSS | S23: PM Inspection for Sultan Sulaiman TPSS | T23: [] | U23: [] | V23: PM Complete | W23: [] | X23: [] | Y23: [] | Z23: 19/02/2022 | AA23: 7091 | AB23: PS_PM_WEK_TPSS_4000449980.pdf
A24: 12384532 | B24: M7 | C24: 23/12/2024 | D24: 0805 | E24: 30/12/2024 | F24: WS10 | G24: IP1020241223 | H24: 4000655176 | K24: NOPR NOPT ORAS OSTS | L24: CLS ACK | M24: PRAL-MRL-WS-STN-MRLTSA Station Titiwangsa | N24: WES Wayside Department | R24: MRWSU001 1003 Inspection - 1 Week Interval | S24: PM Inspection for Titiwangsa - PM COMPLETE | T24: [{'task': '0001', 'description': '1001'}] | U24: [{'staff_id': '10011858', 'name': 'NAZRULSHAH BIN MOHAMAD JUBERI', 'plan_start_date_time': '00:00:00', 'plan_end_date_time': '00:00:00', 'total_hours': '1'}] | V24: I'm complete | W24: [{'item': '0001', 'object_part': 'Station Power Supply', 'damage': ''}] | X24: [{'item': '0001', 'cause': 'Scheduled maintenance'}] | Y24: [{'item': '0001', 'activity': 'Check / Inspect -'}] | Z24: 23/12/2024 | AA24: 11858 | AB24: PS_PM_WEK_StationInspection_4000655176.pdf
A25: 12385412 | B25: M7 | C25: 26/12/2024 | D25: 0805 | E25: 02/01/2025 | F25: WS10 | G25: IP1020241226 | H25: 4000655182 | K25: NOPR NOPT ORAS OSTS | L25: CLS ACK | M25: PRAL-MRL-WS-STN-MRLHAH Station Hang Tuah | N25: WES Wayside Department | Q25: MRWSU001 1003 Inspection - 1 Week Interval | R25: PM Inspection for Hang Tuah Station | S25: PM COMPLETE | T25: [{'task': '0001', 'description': '1001'}] | U25: [{'staff_id': '10007114', 'name': 'DINESH KUMAR A/L VARUTHER RAJOO', 'plan_start_date_time': '00:00:00', 'plan_end_date_time': '00:00:00', 'total_hours': ''}] | V25: Pm complete. | W25: [{'item': '0001', 'object_part': 'Station Power Supply', 'damage': ''}] | X25: [{'item': '0001', 'cause': 'Scheduled maintenance'}] | Y25: [{'item': '0001', 'activity': 'Check/Inspect -'}] | Z25: 26/12/2024 | AA25: 7114 | AB25: PS_PM_WEK_StationInspection_4000655182.pdf
A26: 12385409 | B26: M7 | C26: 25/12/2024 | D26: 0805 | E26: 01/01/2025 | F26: WS20 | G26: IP1020241225 | H26: 4000655181 | K26: NOPR NOPT ORAS OSTS | L26: CLS ACK | M26: PRAL-MRL-WS-STN-MRLRAN Station Raja Chulan | N26: WES Wayside Department | R26: MRWSU001 1003 Inspection - 1 Week Interval | S26: - PM COMPLETE | T26: [{'task': '0001', 'description': '1001'}] | U26: [{'staff_id': '10007114', 'name': 'DINESH KUMAR A/L VARUTHER RAJOO', 'plan_start_date_time': '00:00:00', 'plan_end_date_time': '00:00:00', 'total_hours': ''}] | W26: [{'item': '0001', 'object_part': 'Station Power Supply', 'damage': ''}] | X26: [{'item': '0001', 'cause': 'Scheduled maintenance'}] | Y26: [{'item': '0001', 'activity': 'Check/Inspect -'}] | Z26: 01/01/2025 | AA26: 7114 | AB26: PS_PM_WEK_StationInspection_4000655181.pdf
A27: 12385135 | B27: M7 | C27: 24/12/2024 | D27: 0805 | E27: 31/12/2024 | F27: WS10 | G27: IP1020241224 | H27: 4000655178 | K27: NOPR NOPT ORAS OSTS | L27: CLS ACK | M27: PRAL-MRL-WS-STN-MRLMKU Station Medan Tuanku | N27: WES Wayside Department | R27: MRWSU001 1003 Inspection - 1 Week Interval | S27: - PM COMPLETE | T27: [{'task': '0001', 'description': '1001'}] | U27: [{'staff_id': '10011858', 'name': 'NAZRULSHAH BIN MOHAMAD JUBERI', 'plan_start_date_time': '00:00:00', 'plan_end_date_time': '00:00:00', 'total_hours': ''}] | V27: Pm complete. | W27: [{'item': '0001', 'object_part': 'Station Power Supply', 'damage': ''}] | X27: [{'item': '0001', 'cause': 'Scheduled maintenance'}] | Y27: [{'item': '0001', 'activity': 'Check / Inspect -'}] | Z27: 31/12/2024 | AA27: 7114 | AB27: PS_PM_WEK_StationInspection_4000655178.pdf
A28: 12385633 | B28: M7 | C28: 26/12/2024 | D28: 0805 | E28: 02/01/2025 | F28: WS10 | G28: IP1020241226 | H28: 4000655183 | K28: NOPR NOPT ORAS OSTS | L28: CLS ACK | M28: PRAL-MRL-WS-STN-MRLIBI Station Imbi | N28: WES Wayside Department | Q28: MRWSU001 1003 Inspection - 1 Week Interval | R28: PM Inspection for Imbi Station | S28: PM COMPLETE | T28: [{'task': '1001', 'description': ''}] | U28: [{'staff_id': '10007114', 'name': 'DINESH KUMAR A/L VARUTHER RAJOO', 'plan_start_date_time': '00:00:00', 'plan_end_date_time': '00:00:00', 'total_hours': ''}] | V28: PM complete | W28: [{'item': '0001', 'object_part': 'Station Power Supply', 'damage': ''}] | X28: [{'item': '0001', 'cause': 'Scheduled maintenance'}] | Y28: [{'item': '0001', 'activity': 'Check/Inspect -'}] | Z28: 26.12.29 | AB28: PS_PM_WEK_StationInspection_4000655183.pdf
A29: 12385722 | B29: M7 | C29: 27/12/2024 | D29: 0805 | E29: 03/01/2025 | F29: WS10 | G29: IP1020241227 | H29: 4000655185 | K29: NOPR NOPT ORAS OSTS | L29: CLS ACK | M29: PRAL-MRL-WS-STN-MRLMAH Station Maharajalela | N29: WES Wayside Department | Q29: MRWSU001 I003 Inspection - 1 Week Interval | R29: PM Inspection for Maharaja Lela Station | S29: PM COMPLETE | T29: [{'task': '0001', 'description': 'I001'}] | U29: [{'staff_id': '10007114', 'name': 'DINESH KUMAR A/L VARUTHER RAJOO', 'plan_start_date_time': '00:00:00', 'plan_end_date_time': '00:00:00', 'total_hours': ''}] | V29: pm complete. | W29: [{'item': '0001', 'object_part': 'Station Power Supply', 'damage': ''}] | X29: [{'item': '0001', 'cause': 'Scheduled maintenance'}] | Y29: [{'item': '0001', 'activity': 'Check/Inspect -'}] | Z29: 27/12/24 | AA29: 11858 | AB29: PS_PM_WEK_StationInspection_4000655185.pdf
A30: 12385903 | B30: M7 | C30: 27/12/2024 | D30: 0805 | E30: 03/01/2025 | F30: WS10 | G30: IP1020241227 | H30: 4000655186 | K30: NOPR NOPT ORAS OSTS | L30: CLS ACK | M30: PRAL-MRL-WS-STN-MRLTUN Station Tun Sambanthan | N30: WES Wayside Department | Q30: MRWSU001 I003 Inspection - 1 Week Interval | R30: PM Inspection for Tun Sambanthan Station | S30: - PM COMPLETE | T30: [{'task': '0001', 'description': '1001'}] | U30: [{'staff_id': '10007114', 'name': 'DINESH KUMAR A/L VARUTHER RAJOO', 'plan_start_date_time': '00:00:00', 'plan_end_date_time': '00:00:00', 'total_hours': ''}] | V30: pm Complete. | W30: [{'item': '0001', 'object_part': 'Station Power Supply', 'damage': ''}] | X30: [{'item': '0001', 'cause': 'Scheduled maintenance'}] | Y30: [{'item': '0001', 'activity': 'Check / Inspect -'}] | Z30: 27/12/2024 | AA30: 19234 | AB30: PS_PM_WEK_StationInspection_4000655186.pdf
A31: 12421846 | B31: M7 | C31: 12/03/2025 | D31: 0805 | E31: 19/03/2025 | F31: WS20 | G31: IP1020250312 | H31: 4000663756 | K31: NOPR NOPT ORAS OSTS | L31: CLS ACK | M31: PRAL-MRL-WS-STN-MRLRAN Station Raja Chulan | N31: WES Wayside Department | Q31: MRWSU001 1003 Inspection - 1 Week Interval | R31: PM Inspection for Raja Chulan Station | S31: -PM COMPLETE | T31: [{'task': '0001', 'description': '1001'}] | U31: [{'staff_id': '10012660', 'name': 'MUHAMAD SHAZWAN BIN\nMOHAMMAD RASUDIN', 'plan_start_date_time': '00:00:00', 'plan_end_date_time': '00:00:00', 'total_hours': ''}] | W31: [{'item': '0001', 'object_part': 'Station Power Supply', 'damage': ''}] | X31: [{'item': '0001', 'cause': 'Scheduled maintenance'}] | Y31: [{'item': '0001', 'activity': 'Check/Inspect -'}] | Z31: 19/03/2025 | AA31: 19924 | AB31: PS_PM_WEK_StationInspection_4000663756.pdf
A32: 12395465 | B32: M7 | C32: 16/01/2025 | D32: 0805 | E32: 23/01/2025 | F32: WS10 | G32: IP1020250116 | H32: 4000655204 | K32: NOPR NOPT ORAS OSTS | L32: CLS ACK | M32: PRAL-MRL-WS-STN-MRLIBI Station Imbi | N32: WES Wayside Department | Q32: MRWSU001 1003 Inspection - 1 Week Interval | R32: PM Inspection for Imbi Station | S32: -PM COMPLETE | T32: [{'task': '0001', 'description': '1001'}] | U32: [{'staff_id': '10012660', 'name': 'MUHAMAD SHAZWAN BIN\nMOHAMMAD RASUDIN', 'plan_start_date_time': '00:00:00', 'plan_end_date_time': '00:00:00', 'total_hours': ''}] | V32: PM Complete | W32: [{'item': '0001', 'object_part': 'Station Power Supply', 'damage': ''}] | X32: [{'item': '0001', 'cause': 'Scheduled maintenance'}] | Y32: [{'item': '0001', 'activity': 'Check / Inspect -'}] | Z32: 23/1/25 | AA32: MORIEZUWAD | AB32: PS_PM_WEK_StationInspection_4000655204.pdf
A33: 12386478 | B33: M7 | C33: 30/12/2024 | D33: 0805 | E33: 06/01/2025 | F33: WS10 | G33: IP1020241230 | H33: 4000655194 | K33: NOPR NOPT ORAS OSTS | L33: CLS ACK | M33: PRAL-MRL-WS-STN-MRLTSA Station Titiwangsa | N33: WES Wayside Department | Q33: MRWSU001 1003 Inspection - 1 Week Interval | R33: PM Inspection for Titiwangsa | S33: PM COMPLETE | T33: [{'task': '0001', 'description': '1001'}] | U33: [{'staff_id': '10007094', 'name': 'MOHAMAD IRZAN BIN YUSOF', 'plan_start_date_time': '00:00:00', 'plan_end_date_time': '00:00:00', 'total_hours': ''}] | V33: Pm complete. | W33: [{'item': '0001', 'object_part': 'Station Power Supply', 'damage': ''}] | X33: [{'item': '0001', 'cause': 'Scheduled maintenance'}] | Y33: [{'item': '0001', 'activity': 'Check / Inspect -'}] | Z33: 30/12/24 | AA33: 7114 | AB33: PS_PM_WEK_StationInspection_4000655194.pdf
A34: 12394678 | B34: M7 | C34: 14/01/2025 | D34: 0805 | E34: 21/01/2025 | F34: WS10 | G34: IP1020250114 | H34: 4000655199 | K34: NOPR NOPT ORAS OSTS | L34: CLS ACK | M34: PRAL-MRL-WS-STN-MRLMKU Station Medan Tuanku | N34: WES Wayside Department | Q34: MRWSU001 I003 Inspection - 1 Week Interval | R34: PM Inspection for Medan Tuanku Station | S34: - PM COMPLETE | T34: [{'task': '0001', 'description': 'I001'}] | U34: [{'staff_id': '10007114', 'name': 'DINESH KUMAR A/L VARUTHER RAJOO', 'plan_start_date_time': '00:00:00', 'plan_end_date_time': '00:00:00', 'total_hours': ''}] | V34: PM complete | W34: [{'item': '0001', 'object_part': 'Station Power Supply', 'damage': ''}] | X34: [{'item': '0001', 'cause': 'Scheduled maintenance'}] | Y34: [{'item': '0001', 'activity': 'Check/Inspect -'}] | Z34: 21/1/2025 | AA34: 7114 | AB34: PS_PM_WEK_StationInspection_4000655199.pdf
A35: 12395464 | B35: M7 | C35: 16/01/2025 | D35: 0805 | E35: 23/01/2025 | F35: WS10 | G35: IP1020250116 | H35: 4000655205 | K35: NOPR NOPT ORAS OSTS | L35: CLS ACK | M35: PRAL-MRL-WS-STN-MRLHAH Station Hang Tuah | N35: WES Wayside Department | Q35: MRWSU001 1003 Inspection - 1 Week Interval | R35: PM Inspection for Hang Tuah Station | S35: - PM COMPLETE | T35: [{'task': '0001', 'description': '1001'}] | U35: [{'staff_id': '10012660', 'name': 'MUHAMAD SHAZWAN BIN', 'plan_start_date_time': '00:00:00', 'plan_end_date_time': '00:00:00', 'total_hours': ''}, {'staff_id': '', 'name': 'MOHAMMAD RASUDIN', 'plan_start_date_time': '', 'plan_end_date_time': '', 'total_hours': ''}] | V35: Pm Complete | W35: [{'item': '0001', 'object_part': 'Station Power Supply', 'damage': ''}] | X35: [{'item': '0001', 'cause': 'Scheduled maintenance'}] | Y35: [{'item': '0001', 'activity': 'Check/Inspect -'}] | Z35: 23/01/2025 | AA35: 7094 | AB35: PS_PM_WEK_StationInspection_4000655205.pdf
A36: 12421845 | B36: M7 | C36: 12/03/2025 | D36: 0805 | E36: 19/03/2025 | F36: WS10 | G36: IP1020250312 | H36: 4000663757 | K36: NOPR NOPT ORAS OSTS | L36: CLS ACK | M36: PRAL-MRL-WS-STN-MRLBNG Station Bukit Bintang | N36: WES Wayside Department | Q36: MRWSU001 1003 Inspection - 1 Week Interval | R36: PM Inspection for Bukit Bintang Station | S36: -PM COMPLETE | T36: [{'task': '0001', 'description': '1001'}] | U36: [{'staff_id': '10012660', 'name': 'MUHAMAD SHAZWAN BIN MOHAMMAD RASUDIN', 'plan_start_date_time': '00:00:00', 'plan_end_date_time': '00:00:00', 'total_hours': ''}] | W36: [{'item': '0001', 'object_part': 'Station Power Supply', 'damage': ''}] | X36: [{'item': '0001', 'cause': 'Scheduled maintenance'}] | Y36: [{'item': '0001', 'activity': 'Check/Inspect -'}] | Z36: 19/03/2025 | AA36: 7094 | AB36: PS_PM_WEK_StationInspection_4000663757.pdf
A37: 11894131 | B37: M7 | C37: 07/01/2022 | D37: 0805 | E37: 13/01/2022 | F37: WS10 | G37: IP1020220107 | H37: 4000443616 | K37: NOPR ORAS | L37: REQ | M37: PRAL-MRL-WS-TPS-MRLMTZ TPSS - Medan Tuanku | N37: WES Wayside Department | Q37: MRWSU001 1003 | R37: PM Inspection for Medan Tuanku TPSS | S37: PM Inspection for Medan Tuanku TPSS | T37: [] | U37: [] | V37: Pm Complete | W37: [] | X37: [] | Y37: [] | Z37: 13/01/2022 | AA37: 7094 | AB37: PS_PM_WEK_TPSS_4000443616.pdf
A38: 12398903 | B38: M7 | C38: 25/01/2025 | D38: 0805 | E38: 01/02/2025 | F38: WS10 | G38: IP1020250125 | H38: 4000655227 | K38: NOPR NOPT ORAS OSTS | L38: CLS ACK | M38: PRAL-MRL-WS-STN-MRLKLS Station KL Sentral | N38: WES Wayside Department | Q38: MRWSU001 1003 Inspection - 1 Week Interval | R38: PM Inspection for KL Sentral Station | S38: PM COMPLETE | T38: [{'task': '0001', 'description': '1001'}] | U38: [{'staff_id': '10019924', 'name': 'AHMAD JURIJ BIN AMIRUDIN', 'plan_start_date_time': '00:00:00', 'plan_end_date_time': '00:00:00', 'total_hours': ''}] | V38: PM Complete | W38: [{'item': '0001', 'object_part': 'Station Power Supply', 'damage': ''}] | X38: [{'item': '0001', 'cause': 'Scheduled maintenance'}] | Y38: [{'item': '0001', 'activity': 'Check/Inspect -'}] | Z38: 01/02/2025 | AA38: 19924 | AB38: PS_PM_WEK_StationInspection_4000655227.pdf
A39: 12398950 | B39: M7 | C39: 26/01/2025 | D39: 0805 | E39: 02/02/2025 | F39: WS10 | G39: IP1020250126 | H39: 4000655230 | K39: NOPR NOPT ORAS OSTS | L39: CLS ACK | M39: PRAL-MRL-WS-BLD-MRLWSP Workshop | N39: WES Wayside Department | Q39: MRWSU001 1003 Inspection - 1 Week Interval | R39: PM Inspection for Workshop Building | S39: - PM COMPLETE | T39: [{'task': '0001', 'description': 1001}] | U39: [{'staff_id': '10019924', 'name': 'AHMAD JURIJ BIN AMIRUDIN', 'plan_start_date_time': '00:00:00', 'plan_end_date_time': '00:00:00', 'total_hours': ''}] | V39: PM Complete | W39: [{'item': '0001', 'object_part': 'Depot Power Supply', 'damage': ''}] | X39: [{'item': '0001', 'cause': 'Scheduled maintenance'}] | Y39: [{'item': '0001', 'activity': 'Check / Inspect -'}] | Z39: 02/02/2025 | AA39: 19924 | AB39: PS_PM_WEK_StationInspection_4000655230.pdf
A40: 11910495 | B40: M7 | C40: 18/02/2022 | D40: 0805 | E40: 24/02/2022 | F40: WS10 | G40: IP1020220218 | H40: 4000450790 | K40: NOPR ORAS | L40: REQ | M40: PRAL-MRL-WS-TPS-MRLMTZ TPSS - Medan Tuanku | N40: WES Wayside Department | Q40: MRWSU001 1003 | R40: PM Inspection for Medan Tuanku TPSS | S40: PM Inspection for Medan Tuanku TPSS | T40: [] | U40: [] | V40: pm complete | W40: [] | X40: [] | Y40: [] | Z40: 24/02/2022 | AA40: 7013 | AB40: PS_PM_WEK_TPSS_4000450790.pdf
...

Sheet work_order
A1: work_order_no | B1: work_order_type | C1: date_opened | D1: cost_centre | E1: priority | F1: assigned_to | G1: maint_act_type | H1: work_centre | I1: maintenance_plant | J1: functional_location | K1: location | L1: superior_equipment | M1: equipment | N1: operations | O1: materials | P1: labour_details | Q1: object_part | R1: cause | S1: damage | T1: action | U1: target | V1: comment | W1: date_closed | X1: supervisor_verification | Y1: status | Z1: filename
A2: 4000441928 | B2: RAIL - Preventive Maintenance Order | C2: 02/01/2022 | D2: 8021131200 | E2: 3-Medium | G2: PVM | H2: WS10 | I2: 0805 Rapid Rail StarRail (Monorail) | J2: PRAL-MRL-WS-TPS-MRLBFZ TPSS - Brickfields | K2: WES Wayside Department | N2: [] | O2: [] | P2: [] | U2: 02/01/2022 | V2: Im complete | W2: 02/01/21 | X2: 7094 | Y2: 3PLN | Z2: PS_PM_WEK_TPSS_4000441928.pdf | AA2: =IF(COUNTIF(Sheet1!A:A, TRIM(Z2))>0, "YES", "NO") -> NO
A3: 4000441929 | B3: RAIL - Preventive Maintenance Order | C3: 03/01/2022 | D3: 8021131200 | E3: 3-Medium | G3: PVM | H3: WS10 | I3: 0805 Rapid Rail StarRail (Monorail) | J3: PRAL-MRL-WS-STN-MRLCIT Station Chow Kit | K3: WES Wayside Department | N3: [{'operation_no': '0010', 'operation_text': 'Weekly Station Inspection'}] | O3: [] | P3: [] | U3: 03/01/2022 | V3: PM complete | W3: 03/01/2022 | X3: 7094 | Y3: 3PLN | Z3: PS_PM_WEK_StationInspection_4000441929.pdf | AA3: =IF(COUNTIF(Sheet1!A:A, TRIM(Z3))>0, "YES", "NO") -> NO
A4: 4000442386 | B4: RAIL - Preventive Maintenance Order | C4: 04/01/2022 | D4: 8021131200 | E4: 3-Medium | G4: PVM | H4: WS10 | I4: 0805 Rapid Rail StarRail (Monorail) | J4: PRAL-MRL-WS-STN-MRLMKU Station Medan Tuanku | K4: WES Wayside Department | N4: [{'operation_no': '0010', 'operation_text': 'Weekly Station Inspection'}] | O4: [{'item_no': '', 'material_no': '', 'description': '', 'required_quantity': '', 'unit_of_measurement': ''}] | P4: [{'staff_id': '', 'name': '', 'plan_start_date_time': '', 'plan_end_date_time': '', 'total_hours': ''}] | U4: 04/01/2022 | V4: pm Complete | W4: 04/01/2022 | Y4: 3PLN | Z4: PS_PM_WEK_StationInspection_4000442386.pdf | AA4: =IF(COUNTIF(Sheet1!A:A, TRIM(Z4))>0, "YES", "NO") -> NO
A5: 4000442388 | B5: RAIL - Preventive Maintenance Order | C5: 05/01/2022 | D5: 8021131200 | E5: 3-Medium | G5: PVM | H5: WS10 | I5: 0805 Rapid Rail StarRail (Monorail) | J5: PRAL-MRL-WS-STN-MRLBNG Station Bukit Bintang | K5: WES Wayside Department | N5: [{'operation_no': '0010', 'operation_text': 'Weekly Station Inspection'}] | O5: [] | P5: [] | U5: 05/01/2022 | V5: pm complete | W5: 05/01/2022 | Y5: 3PLN | Z5: PS_PM_WEK_StationInspection_4000442388.pdf | AA5: =IF(COUNTIF(Sheet1!A:A, TRIM(Z5))>0, "YES", "NO") -> NO
A6: 4000442389 | B6: RAIL - Preventive Maintenance Order | C6: 05/01/2022 | D6: 8021131200 | E6: 3-Medium | G6: PVM | H6: WS10 | I6: 0805 Rapid Rail StarRail (Monorail) | J6: PRAL-MRL-WS-STN-MRLRAN Station Raja Chulan | K6: WES Wayside Department | N6: [{'operation_no': '0010', 'operation_text': 'Weekly Station Inspection'}] | O6: [] | P6: [] | U6: 05/01/2022 | V6: pm complete | W6: 05/01/2022 | Y6: 3PLN | Z6: PS_PM_WEK_StationInspection_4000442389.pdf | AA6: =IF(COUNTIF(Sheet1!A:A, TRIM(Z6))>0, "YES", "NO") -> NO
A7: 4000442392 | B7: RAIL - Preventive Maintenance Order | C7: 06/01/2022 | D7: 8021131200 | E7: 3-Medium | G7: PVM | H7: WS10 | I7: 0805 Rapid Rail StarRail (Monorail) | J7: PRAL-MRL-WS-TPS-MRLMTZ TPSS - Medan Tuanku | K7: WES Wayside Department | N7: ['Weekly TPSS Inspection'] | O7: [] | P7: [] | U7: 06/01/2022 | V7: PM complete | W7: 06/01/2022 | X7: 7013 | Y7: 3PLN | Z7: PS_PM_WEK_TPSS_4000442392.pdf | AA7: =IF(COUNTIF(Sheet1!A:A, TRIM(Z7))>0, "YES", "NO") -> NO
A8: 4000443598 | B8: RAIL - Preventive Maintenance Order | C8: 07/01/2022 | D8: 8021131200 | E8: 3-Medium | G8: PVM | H8: WS10 | I8: 0805 Rapid Rail StarRail (Monorail) | J8: PRAL-MRL-WS-STN-MRLMAH Station Maharajalela | K8: WES Wayside Department | N8: [{'operation_no': '0010', 'operation_text': 'Weekly Station Inspection'}] | O8: [{'item_no': '', 'material_no': '', 'description': '', 'required_quantity': '', 'unit_of_measurement': ''}] | P8: [{'staff_id': '', 'name': '', 'plan_start_date_time': '', 'plan_end_date_time': '', 'total_hours': ''}] | U8: 07/01/2022 | V8: Pm complete | W8: 07/01/2022 | X8: 7099 | Y8: 3PLN | Z8: PS_PM_WEK_StationInspection_4000443598.pdf | AA8: =IF(COUNTIF(Sheet1!A:A, TRIM(Z8))>0, "YES", "NO") -> NO
A9: 4000443599 | B9: RAIL - Preventive Maintenance Order | C9: 07/01/2022 | D9: 8021131200 | E9: 3-Medium | G9: PVM | H9: WS10 | I9: 0805 Rapid Rail StarRail (Monorail) | J9: PRAL-MRL-WS-STN-MRLTUN Station Tun Sambanthan | K9: WES Wayside Department | N9: [{'operation_no': '0010', 'operation_text': 'Weekly Station Inspection'}] | O9: [] | P9: [] | U9: 07/01/2022 | V9: Pm complete | W9: 07/012022 | X9: 7099 | Y9: 3PLN | Z9: PS_PM_WEK_StationInspection_4000443599.pdf | AA9: =IF(COUNTIF(Sheet1!A:A, TRIM(Z9))>0, "YES", "NO") -> NO
A10: 4000443602 | B10: RAIL - Preventive Maintenance Order | C10: 08/01/2022 | D10: 8021131200 | E10: 3-Medium | G10: PVM | H10: WS10 | I10: 0805 Rapid Rail StarRail (Monorail) | J10: PRAL-MRL-WS-STN-MRLKLS Station KL Sentral | K10: WES Wayside Department | N10: [{'operation_no': '0010', 'operation_text': 'Weekly Station Inspection'}] | O10: [] | P10: [] | U10: 08/01/2022 | V10: Pm complete | W10: 08/01/2022 | X10: 7091 | Y10: 3PLN | Z10: PS_PM_WEK_StationInspection_4000443602.pdf | AA10: =IF(COUNTIF(Sheet1!A:A, TRIM(Z10))>0, "YES", "NO") -> NO
A11: 4000443603 | B11: RAIL - Preventive Maintenance Order | C11: 08/01/2022 | D11: 8021131200 | E11: 3-Medium | G11: PVM | H11: WS10 | I11: 0805 Rapid Rail StarRail (Monorail) | J11: PRAL-MRL-WS-TPS-MRLSSZ TPSS - Sultan Sulaiman | K11: WES Wayside Department | N11: ['Weekly TPSS Inspection'] | O11: [] | P11: [] | U11: 08/01/2022 | V11: Pm Complete | W11: 08/01/2022 | X11: 7091 | Y11: 3PLN | Z11: PS_PM_WEK_TPSS_4000443603.pdf | AA11: =IF(COUNTIF(Sheet1!A:A, TRIM(Z11))>0, "YES", "NO") -> NO
A12: 4000443604 | B12: RAIL - Preventive Maintenance Order | C12: 09/01/2022 | D12: 8021131200 | E12: 3-Medium | G12: PVM | H12: WS10 | I12: 0805 Rapid Rail StarRail (Monorail) | J12: PRAL-MRL-WS-BLD-MRLWSP Workshop | K12: WES Wayside Department | N12: [{'operation_no': '0010', 'operation_text': 'Weekly Station Inspection'}] | O12: [] | P12: [{'staff_id': '', 'name': 'Mm mi', 'plan_start_date_time': '', 'plan_end_date_time': '', 'total_hours': ''}] | U12: 09/01/2022 | V12: pm complete | W12: 09/01/2022 | X12: 7094 | Y12: 3PLN | Z12: PS_PM_WEK_StationInspection_4000443604.pdf | AA12: =IF(COUNTIF(Sheet1!A:A, TRIM(Z12))>0, "YES", "NO") -> NO
A13: 4000443605 | B13: RAIL - Preventive Maintenance Order | C13: 09/01/2022 | D13: 8021131200 | E13: 3-Medium | G13: PVM | H13: WS10 | I13: 0805 Rapid Rail StarRail (Monorail) | J13: PRAL-MRL-WS-TPS-MRLBFZ TPSS - Brickfields | K13: WES Wayside Department | N13: ['Weekly TPSS Inspection'] | O13: [] | P13: [] | U13: 09/01/2022 | V13: Im complete | W13: 09/01/22 | X13: MAHADI | Y13: 3PLN | Z13: PS_PM_WEK_TPSS_4000443605.pdf | AA13: =IF(COUNTIF(Sheet1!A:A, TRIM(Z13))>0, "YES", "NO") -> NO
A14: 4000443607 | B14: RAIL - Preventive Maintenance Order | C14: 10/01/2022 | D14: 8021131200 | E14: 3-Medium | G14: PVM | H14: WS10 | I14: 0805 Rapid Rail StarRail (Monorail) | J14: PRAL-MRL-WS-STN-MRLTSA Station Titiwangsa | K14: WES Wayside Department | N14: [{'operation_no': '0010', 'operation_text': 'Weekly Station Inspection'}] | O14: [] | P14: [] | U14: 10/01/2022 | V14: PM complete | W14: 10/01/2022 | X14: 7013 | Y14: 3PLN | Z14: PS_PM_WEK_StationInspection_4000443607.pdf | AA14: =IF(COUNTIF(Sheet1!A:A, TRIM(Z14))>0, "YES", "NO") -> NO
A15: 4000443608 | B15: RAIL - Preventive Maintenance Order | C15: 11/01/2022 | D15: 8021131200 | E15: 3-Medium | G15: PVM | H15: WS10 | I15: 0805 Rapid Rail StarRail (Monorail) | J15: PRAL-MRL-WS-STN-MRLBAS Station Bukit Nanas | K15: WES Wayside Department | N15: [{'operation_no': '0010', 'operation_text': 'Weekly Station Inspection'}] | O15: [] | P15: [] | U15: 11/01/2022 | V15: Pm Complete | W15: 11/01/2022 | X15: 7099 | Y15: 3PLN | Z15: PS_PM_WEK_StationInspection_4000443608.pdf | AA15: =IF(COUNTIF(Sheet1!A:A, TRIM(Z15))>0, "YES", "NO") -> NO
A16: 4000443610 | B16: RAIL - Preventive Maintenance Order | C16: 11/01/2022 | D16: 8021131200 | E16: 3-Medium | G16: PVM | H16: WS10 | I16: 0805 Rapid Rail StarRail (Monorail) | J16: PRAL-MRL-WS-STN-MRLMKU Station Medan Tuanku | K16: WES Wayside Department | N16: [{'operation_no': '0010', 'operation_text': 'Weekly Station Inspection'}] | O16: [{'item_no': '', 'material_no': '', 'description': '', 'required_quantity': '', 'unit_of_measurement': ''}] | P16: [{'staff_id': '', 'name': '', 'plan_start_date_time': '', 'plan_end_date_time': '', 'total_hours': ''}] | Q16: 11/01/2022 | U16: 11/01/2022 | V16: Pm Complete | W16: 11/01/2022 | X16: 7099 | Y16: 3PLN | Z16: PS_PM_WEK_StationInspection_4000443610.pdf | AA16: =IF(COUNTIF(Sheet1!A:A, TRIM(Z16))>0, "YES", "NO") -> NO
A17: 4000443612 | B17: RAIL - Preventive Maintenance Order | C17: 12/01/2022 | D17: 8021131200 | E17: 3-Medium | G17: PVM | H17: WS10 | I17: 0805 Rapid Rail StarRail (Monorail) | J17: PRAL-MRL-WS-STN-MRLBNG Station Bukit Bintang | K17: WES Wayside Department | N17: [{'operation_no': '0010', 'operation_text': 'Weekly Station Inspection'}] | O17: [] | P17: [] | U17: 12/01/2022 | V17: PM Complete | W17: 12/01/2022 | X17: 7099 | Y17: 3PLN | Z17: PS_PM_WEK_StationInspection_4000443612.pdf | AA17: =IF(COUNTIF(Sheet1!A:A, TRIM(Z17))>0, "YES", "NO") -> NO
A18: 4000443613 | B18: RAIL - Preventive Maintenance Order | C18: 12/01/2022 | D18: 8021131200 | E18: 3-Medium | G18: PVM | H18: WS10 | I18: 0805 Rapid Rail StarRail (Monorail) | J18: PRAL-MRL-WS-STN-MRLRAN Station Raja Chulan | K18: WES Wayside Department | N18: [{'operation_no': '0010', 'operation_text': 'Weekly Station Inspection'}] | O18: [] | P18: [] | U18: 12/01/2022 | V18: PM CompLETE | W18: 12/01/2022 | X18: 7099 | Y18: 3PLN | Z18: PS_PM_WEK_StationInspection_4000443613.pdf | AA18: =IF(COUNTIF(Sheet1!A:A, TRIM(Z18))>0, "YES", "NO") -> NO
A19: 4000443614 | B19: RAIL - Preventive Maintenance Order | C19: 13/01/2022 | D19: 8021131200 | E19: 3-Medium | G19: PVM | H19: WS10 | I19: 0805 Rapid Rail StarRail (Monorail) | J19: PRAL-MRL-WS-STN-MRLHAH Station Hang Tuah | K19: WES Wayside Department | N19: [{'operation_no': '0010', 'operation_text': 'Weekly Station Inspection'}] | O19: [] | P19: [] | U19: 13/01/2022 | V19: Pm Complete | W19: 13/01/2022 | X19: 7094 | Y19: 3PLN | Z19: PS_PM_WEK_StationInspection_4000443614.pdf | AA19: =IF(COUNTIF(Sheet1!A:A, TRIM(Z19))>0, "YES", "NO") -> NO
A20: 4000443615 | B20: RAIL - Preventive Maintenance Order | C20: 13/01/2022 | D20: 8021131200 | E20: 3-Medium | G20: PVM | H20: WS10 | I20: 0805 Rapid Rail StarRail (Monorail) | J20: PRAL-MRL-WS-STN-MRLIBI Station Imbi | K20: WES Wayside Department | N20: [{'operation_no': '0010', 'operation_text': 'Weekly Station Inspection'}] | O20: [] | P20: [] | U20: 13/01/2022 | V20: Pm complete | W20: 13/01/2022 | X20: 7094 | Y20: 3PLN | Z20: PS_PM_WEK_StationInspection_4000443615.pdf | AA20: =IF(COUNTIF(Sheet1!A:A, TRIM(Z20))>0, "YES", "NO") -> NO
A21: 4000443616 | B21: RAIL - Preventive Maintenance Order | C21: 13/01/2022 | D21: 8021131200 | E21: 3-Medium | G21: PVM | H21: WS10 | I21: 0805 Rapid Rail StarRail (Monorail) | J21: PRAL-MRL-WS-TPS-MRLMTZ TPSS - Medan Tuanku | K21: WES Wayside Department | N21: ['Weekly TPSS Inspection'] | O21: [] | P21: [] | U21: 13/01/2022 | V21: Pm Complete | W21: 13/01/2022 | X21: 7094 | Y21: 3PLN | Z21: PS_PM_WEK_TPSS_4000443616.pdf | AA21: =IF(COUNTIF(Sheet1!A:A, TRIM(Z21))>0, "YES", "NO") -> NO
A22: 4000444202 | B22: RAIL - Preventive Maintenance Order | C22: 14/01/2022 | D22: 8021131200 | E22: 3-Medium | G22: PVM | H22: WS10 | I22: 0805 Rapid Rail StarRail (Monorail) | J22: PRAL-MRL-WS-STN-MRLMAH Station Maharajalela | K22: WES Wayside Department | N22: [{'operation_no': '0010', 'operation_text': 'Weekly Station Inspection'}] | O22: [] | P22: [] | U22: 14/01/2022 | V22: Pm complete | W22: 14/01/2022 | X22: 7091 | Y22: 3PLN | Z22: PS_PM_WEK_StationInspection_4000444202.pdf | AA22: =IF(COUNTIF(Sheet1!A:A, TRIM(Z22))>0, "YES", "NO") -> NO
A23: 4000444203 | B23: RAIL - Preventive Maintenance Order | C23: 14/01/2022 | D23: 8021131200 | E23: 3-Medium | G23: PVM | H23: WS10 | I23: 0805 Rapid Rail StarRail (Monorail) | J23: PRAL-MRL-WS-STN-MRLTUN Station Tun Sambanthan | K23: WES Wayside Department | N23: [{'operation_no': '0010', 'operation_text': 'Weekly Station Inspection'}] | O23: [] | P23: [] | U23: 14/01/2022 | V23: Pm complete | W23: 14/01/2022 | X23: 7091 | Y23: 3PLN | Z23: PS_PM_WEK_StationInspection_4000444203.pdf | AA23: =IF(COUNTIF(Sheet1!A:A, TRIM(Z23))>0, "YES", "NO") -> NO
A24: 4000444204 | B24: RAIL - Preventive Maintenance Order | C24: 14/01/2022 | D24: 8021131200 | E24: 3-Medium | G24: PVM | H24: WS10 | I24: 0805 Rapid Rail StarRail (Monorail) | J24: PRAL-MRL-WS-TPS-MRLHTZ TPSS - Hang Tuah | K24: WES Wayside Department | N24: ['0010 Weekly TPSS Inspection'] | O24: [] | P24: [] | U24: 14/01/2022 | V24: pm complete | W24: 14/01/2022 | X24: 7091 | Y24: 3PLN | Z24: PS_PM_WEK_TPSS_4000444204.pdf | AA24: =IF(COUNTIF(Sheet1!A:A, TRIM(Z24))>0, "YES", "NO") -> NO
A25: 4000444206 | B25: RAIL - Preventive Maintenance Order | C25: 15/01/2022 | D25: 8021131200 | E25: 3-Medium | G25: PVM | H25: WS10 | I25: 0805 Rapid Rail StarRail (Monorail) | J25: PRAL-MRL-WS-STN-MRLKLS Station KL Sentral | K25: WES Wayside Department | N25: [{'operation_no': '0010', 'operation_text': 'Weekly Station Inspection'}] | O25: [] | P25: [] | U25: 15/01/2022 | V25: PM complete | W25: 15/01/2022 | X25: 7091 | Y25: 3PLN | Z25: PS_PM_WEK_StationInspection_4000444206.pdf | AA25: =IF(COUNTIF(Sheet1!A:A, TRIM(Z25))>0, "YES", "NO") -> NO
A26: 4000444207 | B26: RAIL - Preventive Maintenance Order | C26: 15/01/2022 | D26: 8021131200 | E26: 3-Medium | G26: PVM | H26: WS10 | I26: 0805 Rapid Rail StarRail (Monorail) | J26: PRAL-MRL-WS-TPS-MRLSSZ TPSS - Sultan Sulaiman | K26: WES Wayside Department | N26: ['Weekly TPSS Inspection'] | O26: [] | P26: [] | U26: 15/01/2022 | V26: PM COMPLETE | W26: 15/01/2022 | X26: 7091 | Y26: 3PLN | Z26: PS_PM_WEK_TPSS_4000444207.pdf | AA26: =IF(COUNTIF(Sheet1!A:A, TRIM(Z26))>0, "YES", "NO") -> NO
A27: 4000444209 | B27: RAIL - Preventive Maintenance Order | C27: 16/01/2022 | D27: 8021131200 | E27: 3-Medium | G27: PVM | H27: WS10 | I27: 0805 Rapid Rail StarRail (Monorail) | J27: PRAL-MRL-WS-TPS-MRLBFZ TPSS - Brickfields | K27: WES Wayside Department | N27: ['Weekly TPSS Inspection'] | O27: [] | P27: [] | U27: 16/01/2022 | V27: Im complete | W27: 16/01/22 | X27: 7091 | Y27: 3PLN | Z27: PS_PM_WEK_TPSS_4000444209.pdf | AA27: =IF(COUNTIF(Sheet1!A:A, TRIM(Z27))>0, "YES", "NO") -> NO
A28: 4000444211 | B28: RAIL - Preventive Maintenance Order | C28: 17/01/2022 | D28: 8021131200 | E28: 3-Medium | G28: PVM | H28: WS10 | I28: 0805 Rapid Rail StarRail (Monorail) | J28: PRAL-MRL-WS-STN-MRLTSA Station Titiwangsa | K28: WES Wayside Department | N28: [{'operation_no': '0010', 'operation_text': 'Weekly Station Inspection'}] | O28: [] | P28: [] | U28: 17/01/2022 | V28: Pm complete | W28: 17/01/2022 | X28: 7091 | Y28: 3PLN | Z28: PS_PM_WEK_StationInspection_4000444211.pdf | AA28: =IF(COUNTIF(Sheet1!A:A, TRIM(Z28))>0, "YES", "NO") -> NO
... A32: 4000445974 | B32: RAIL - Preventive Maintenance Order | C32: 19/01/2022 | D32: 8021131200 | E32: 3-Medium | G32: PVM | H32: WS10 | I32: 0805 Rapid Rail StarRail (Monorail) | J32: PRAL-MRL-WS-STN-MRLRAN Station Raja Chulan | K32: WES Wayside Department | N32: [{'operation_no': '0010', 'operation_text': 'Weekly Station Inspection'}] | O32: [{'item_no': '', 'material_no': '', 'description': '', 'required_quantity': '', 'unit_of_measurement': ''}] | P32: [{'staff_id': '', 'name': '', 'plan_start_date_time': '', 'plan_end_date_time': '', 'total_hours': ''}] | U32: 19/01/2022 | V32: PM COMPLETE | W32: 19/01/2022 | X32: 7094 | Y32: 3PLN | Z32: PS_PM_WEK_StationInspection_4000445974.pdf | AA32: =IF(COUNTIF(Sheet1!A:A, TRIM(Z32))>0, "YES", "NO") -> NO
A33: 4000445975 | B33: RAIL - Preventive Maintenance Order | C33: 20/01/2022 | D33: 8021131200 | E33: 3-Medium | G33: PVM | H33: WS10 | I33: 0805 Rapid Rail StarRail (Monorail) | J33: PRAL-MRL-WS-STN-MRLHAH Station Hang Tuah | K33: WES Wayside Department | N33: [{'operation_no': '0010', 'operation_text': 'Weekly Station Inspection'}] | O33: [] | P33: [] | U33: 20/01/2022 | V33: PM complete | W33: 20/01/2022 | Y33: 3PLN | Z33: PS_PM_WEK_StationInspection_4000445975.pdf | AA33: =IF(COUNTIF(Sheet1!A:A, TRIM(Z33))>0, "YES", "NO") -> NO
A34: 4000445976 | B34: RAIL - Preventive Maintenance Order | C34: 20/01/2022 | D34: 8021131200 | E34: 3-Medium | G34: PVM | H34: WS10 | I34: 0805 Rapid Rail StarRail (Monorail) | J34: PRAL-MRL-WS-STN-MRLIBI Station Imbi | K34: WES Wayside Department | N34: [{'operation_no': '0010', 'operation_text': 'Weekly Station Inspection'}] | O34: [] | P34: [] | U34: 20/01/2022 | V34: Pm complete | W34: 20/01/2022 | X34: 7094 | Y34: 3PLN | Z34: PS_PM_WEK_StationInspection_4000445976.pdf | AA34: =IF(COUNTIF(Sheet1!A:A, TRIM(Z34))>0, "YES", "NO") -> NO
A35: 4000445977 | B35: RAIL - Preventive Maintenance Order | C35: 20/01/2022 | D35: 8021131200 | E35: 3-Medium | G35: PVM | H35: WS10 | I35: 0805 Rapid Rail StarRail (Monorail) | J35: PRAL-MRL-WS-TPS-MRLMTZ TPSS - Medan Tuanku | K35: WES Wayside Department | N35: ['Weekly TPSS Inspection'] | O35: [] | P35: [] | U35: 20/01/2022 | V35: Pm complete | W35: 20/01/2022 | X35: 7094 | Y35: 3PLN | Z35: PS_PM_WEK_TPSS_4000445977.pdf | AA35: =IF(COUNTIF(Sheet1!A:A, TRIM(Z35))>0, "YES", "NO") -> NO
A36: 4000445978 | B36: RAIL - Preventive Maintenance Order | C36: 21/01/2022 | D36: 8021131200 | E36: 3-Medium | G36: PVM | H36: WS10 | I36: 0805 Rapid Rail StarRail (Monorail) | J36: PRAL-MRL-WS-STN-MRLMAH Station Maharajalela | K36: WES Wayside Department | N36: [{'operation_no': '0010', 'operation_text': 'Weekly Station Inspection'}] | O36: [] | P36: [] | U36: 21/01/2022 | V36: PM complete | W36: 21/01/2022 | X36: 7091 | Y36: 3PLN | Z36: PS_PM_WEK_StationInspection_4000445978.pdf | AA36: =IF(COUNTIF(Sheet1!A:A, TRIM(Z36))>0, "YES", "NO") -> NO
A37: 4000445979 | B37: RAIL - Preventive Maintenance Order | C37: 21/01/2022 | D37: 8021131200 | E37: 3-Medium | G37: PVM | H37: WS10 | I37: 0805 Rapid Rail StarRail (Monorail) | J37: PRAL-MRL-WS-STN-MRLTUN Station Tun Sambanthan | K37: WES Wayside Department | N37: [{'operation_no': '0010', 'operation_text': 'Weekly Station Inspection'}] | O37: [] | P37: [] | U37: 21/01/2022 | V37: Pm complete | W37: 21/01/2022 | X37: 7091 | Y37: 3PLN | Z37: PS_PM_WEK_StationInspection_4000445979.pdf | AA37: =IF(COUNTIF(Sheet1!A:A, TRIM(Z37))>0, "YES", "NO") -> NO
A38: 4000445980 | B38: RAIL - Preventive Maintenance Order | C38: 21/01/2022 | D38: 8021131200 | E38: 3-Medium | G38: PVM | H38: WS10 | I38: 0805 Rapid Rail StarRail (Monorail) | J38: PRAL-MRL-WS-TPS-MRLHTZ TPSS - Hang Tuah | K38: WES Wayside Department | N38: [] | O38: [] | P38: [] | U38: 21/01/2022 | V38: Pm complete | W38: 21/01/2022 | X38: 7091 | Y38: 3PLN | Z38: PS_PM_WEK_TPSS_4000445980.pdf | AA38: =IF(COUNTIF(Sheet1!A:A, TRIM(Z38))>0, "YES", "NO") -> NO
A39: 4000445983 | B39: RAIL - Preventive Maintenance Order | C39: 22/01/2022 | D39: 8021131200 | E39: 3-Medium | G39: PVM | H39: WS10 | I39: 0805 Rapid Rail StarRail (Monorail) | J39: PRAL-MRL-WS-TPS-MRLSSZ TPSS - Sultan Sulaiman | K39: WES Wayside Department | N39: [] | O39: [] | P39: [] | U39: 22/01/2022 | V39: Pm complete | W39: 22/01/2022 | X39: 7091 | Y39: 3PLN | Z39: PS_PM_WEK_TPSS_4000445983.pdf | AA39: =IF(COUNTIF(Sheet1!A:A, TRIM(Z39))>0, "YES", "NO") -> NO
A40: 4000445985 | B40: RAIL - Preventive Maintenance Order | C40: 23/01/2022 | D40: 8021131200 | E40: 3-Medium | G40: PVM | H40: WS10 | I40: 0805 Rapid Rail StarRail (Monorail) | J40: PRAL-MRL-WS-TPS-MRLBFZ TPSS - Brickfields | K40: WES Wayside Department | N40: ['Weekly TPSS Inspection'] | O40: [] | P40: [] | U40: 23/01/2022 | V40: I'm complete | W40: 23/01/22 | X40: 7091 | Y40: 3PLN | Z40: PS_PM_WEK_TPSS_4000445985.pdf | AA40: =IF(COUNTIF(Sheet1!A:A, TRIM(Z40))>0, "YES", "NO") -> NO
A41: 4000445986 | B41: RAIL - Preventive Maintenance Order | C41: 24/01/2022 | D41: 8021131200 | E41: 3-Medium | G41: PVM | H41: WS10 | I41: 0805 Rapid Rail StarRail (Monorail) | J41: PRAL-MRL-WS-STN-MRLCIT Station Chow Kit | K41: WES Wayside Department | N41: [{'operation_no': '0010', 'operation_text': 'Weekly Station Inspection'}] | O41: [] | P41: [] | U41: 24/01/2022 | V41: pm complete | W41: 24/01/2022 | X41: 7013 | Y41: 3PLN | Z41: PS_PM_WEK_StationInspection_4000445986.pdf | AA41: =IF(COUNTIF(Sheet1!A:A, TRIM(Z41))>0, "YES", "NO") -> NO
A42: 4000445987 | B42: RAIL - Preventive Maintenance Order | C42: 24/01/2022 | D42: 8021131200 | E42: 3-Medium | G42: PVM | H42: WS10 | I42: 0805 Rapid Rail StarRail (Monorail) | J42: PRAL-MRL-WS-STN-MRLTSA Station Titiwangsa | K42: WES Wayside Department | N42: [{'operation_no': '0010', 'operation_text': 'Weekly Station Inspection'}] | O42: [] | P42: [] | U42: 24/01/2022 | V42: pm complete | W42: 24/1/22 | X42: 7013 | Y42: 3PLN | Z42: PS_PM_WEK_StationInspection_4000445987.pdf | AA42: =IF(COUNTIF(Sheet1!A:A, TRIM(Z42))>0, "YES", "NO") -> NO
A43: 4000445988 | B43: RAIL - Preventive Maintenance Order | C43: 25/01/2022 | D43: 8021131200 | E43: 3-Medium | G43: PVM | H43: WS10 | I43: 0805 Rapid Rail StarRail (Monorail) | J43: PRAL-MRL-WS-STN-MRLBAS Station Bukit Nanas | K43: WES Wayside Department | N43: [{'operation_no': '0010', 'operation_text': 'Weekly Station Inspection'}] | O43: [] | P43: [] | U43: 25/01/2022 | V43: pM complete | W43: 25/01/2022 | X43: 7013 | Y43: 3PLN | Z43: PS_PM_WEK_StationInspection_4000445988.pdf | AA43: =IF(COUNTIF(Sheet1!A:A, TRIM(Z43))>0, "YES", "NO") -> NO
...

Sheet Sheet1
A1: PS_PM_WEK_TPSS_4000575043.pdf
A2: PS_PM_WEK_TPSS_4000581527.pdf
A3: PS_PM_WEK_TPSS_4000581545.pdf
A4: PS_PM_WEK_TPSS_4000581563.pdf
A5: PS_PM_WEK_TPSS_4000581581.pdf
A6: PS_PM_WEK_TPSS_4000584004.pdf
A7: PS_PM_WEK_TPSS_4000584023.pdf
A8: PS_PM_WEK_TPSS_4000590401.pdf
A9: PS_PM_WEK_TPSS_4000590438.pdf
A10: PS_PM_WEK_TPSS_4000590473.pdf
A11: PS_PM_WEK_TPSS_4000593547.pdf
A12: PS_PM_WEK_TPSS_4000599617.pdf
... A70: PS_PM_YRL_TPSS_4000590453.pdf
